Starting...,  2021-10-26 17:59:53.082245
Folders done, 2021-10-26 18:05:09.396279
multiprocessing.pool.RemoteTraceback: 
"""
Traceback (most recent call last):
  File "/usr/lib64/python3.6/multiprocessing/pool.py", line 119, in worker
    result = (True, func(*args, **kwds))
  File "/usr/lib64/python3.6/multiprocessing/pool.py", line 47, in starmapstar
    return list(itertools.starmap(args[0], args[1]))
  File "main.py", line 85, in addCsvData
    im = Image.open(urlopen(link))
  File "/usr/local/lib64/python3.6/site-packages/PIL/Image.py", line 3024, in open
    "cannot identify image file %r" % (filename if filename else fp)
PIL.UnidentifiedImageError: cannot identify image file <_io.BytesIO object at 0x7f9431ab6db0>
"""

The above exception was the direct cause of the following exception:

Traceback (most recent call last):
  File "main.py", line 161, in <module>
    csvOut = processPool.starmap(addCsvData, csvData)
  File "/usr/lib64/python3.6/multiprocessing/pool.py", line 274, in starmap
    return self._map_async(func, iterable, starmapstar, chunksize).get()
  File "/usr/lib64/python3.6/multiprocessing/pool.py", line 644, in get
    raise self._value
PIL.UnidentifiedImageError: cannot identify image file <_io.BytesIO object at 0x7f9431ab6db0>
cannot identify image file <_io.BytesIO object at 0x7f9431ab6db0> 2021-10-27 16:39:50.906348
